<?xml version="1.0"?>
<robot name="gripper_task" xmlns:xacro="http://wiki.ros.org/xacro">

	<!-- define relative movement to get to gripper_description/ -->
	<xacro:property name="path_to_top" value="../.."/>

  <!-- include the mujoco settings xacro -->
	<xacro:include filename="${path_to_top}/urdf/mujoco/xacro/mujoco.xacro"/>
	<xacro:mujoco_settings/>

	<!-- include the gripper only -->
	<xacro:include filename="${path_to_top}/xacro/gripper.xacro"/>
	<xacro:add_gripper path_to_top="${path_to_top}"/>

  <!-- attach gripper to the ground for gazebo -->
	<link name="world"/>
	<joint name="world_to_base" type="prismatic">
		<origin xyz="0 0 0.335" rpy="${pi} 0 0"/> <!-- 0.325 is fingertips just not touching-->
		<axis xyz="0 0 1" rpy="0 0 0"/>
		<parent link="world"/>
		<child link="gripper_base_link"/>
		<limit effort="1e3" 
        			 lower="-1"
        			 upper="1"
        			 velocity="1"/>
    <dynamics damping="1"/>
	</joint>
		
</robot>
