<?xml version='1.0' encoding='UTF-8'?>
<mujoco model="gripper">
    <compiler angle="radian" meshdir="./meshes_mujoco/"/>
    <size njmax="3200" nconmax="800"/>
    <asset>
        <mesh name="main body visual" file="main body visual.STL"/>
        <mesh name="nut visual" file="nut visual.STL"/>
        <mesh name="nut collision" file="nut collision.STL"/>
        <mesh name="platform only visual" file="platform only visual.STL"/>
        <mesh name="platform only collision" file="platform only collision.STL"/>
        <mesh name="palm visual" file="palm visual.STL"/>
        <mesh name="palm collision" file="palm collision.STL"/>
    </asset>
    <worldbody>
        <geom pos="0 0 1" quat="0 1 0 0" type="mesh" contype="0" conaffinity="0" group="1" mesh="main body visual"/>
        <geom size="0.03 0.05" pos="0 0 1" quat="0 1 0 0" type="cylinder"/>
        <body name="finger_1_intermediate" pos="0 0 1" quat="1.6581e-12 0.707107 5.12042e-12 -0.707107">
            <inertial pos="0 0 0" quat="0.37634 0.403447 0.585982 0.593484" mass="0.1" diaginertia="0.000166494 0.00015418 3.54554e-05"/>
            <joint name="finger_1_prismatic_joint" pos="0 0 0" axis="0 1 0" type="slide" limited="true" range="0.049 0.134" damping="1"/>
            <geom type="mesh" contype="0" conaffinity="0" group="1" mesh="nut visual"/>
            <geom type="mesh" mesh="nut collision"/>
            <body name="finger_1" pos="0 0 0">
                <inertial pos="0.00790482 -0.000428944 0" quat="0.291337 0.573406 0.417602 0.641823" mass="0.106528" diaginertia="0.000258979 0.000257241 4.77119e-05"/>
                <joint name="finger_1_revolute_joint" pos="0 0 0" axis="0 0 1" limited="true" range="-0.7 0.7" damping="1"/>
                <geom type="mesh" contype="0" conaffinity="0" group="1" mesh="platform only visual"/>
                <geom type="mesh" mesh="platform only collision"/>
                <geom size="0.01175 0.014 0.00045" pos="0.14075 -0.007 0" quat="0.707107 0.707107 0 0" type="box" contype="0" conaffinity="0" group="1"/>
                <geom size="0.01175 0.014 0.00045" pos="0.14075 -0.007 0" quat="0.707107 0.707107 0 0" type="box"/>
                <body name="finger_1_segment_link_2" pos="0.1525 -0.007 0" quat="0.707107 0.707107 0 0">
                    <inertial pos="0 0 0" quat="0 0.707107 0 0.707107" mass="0.00652778" diaginertia="1.62814e-06 1.2021e-06 4.26922e-07"/>
                    <joint name="finger_1_segment_joint_1" pos="0 0 0" axis="0 1 0" limited="true" range="-1 1" damping="0.01" stiffness="5"/>
                    <geom size="0.01175 0.014 0.00045" pos="0.01175 0 0" type="box" contype="0" conaffinity="0" group="1"/>
                    <geom size="0.01175 0.014 0.00045" pos="0.01175 0 0" type="box"/>
                    <body name="finger_1_segment_link_3" pos="0.0235 0 0">
                        <inertial pos="0 0 0" quat="0 0.707107 0 0.707107" mass="0.00652778" diaginertia="1.62814e-06 1.2021e-06 4.26922e-07"/>
                        <joint name="finger_1_segment_joint_2" pos="0 0 0" axis="0 1 0" limited="true" range="-1 1" damping="0.01" stiffness="5"/>
                        <geom size="0.01175 0.014 0.00045" pos="0.01175 0 0" type="box" contype="0" conaffinity="0" group="1"/>
                        <geom size="0.01175 0.014 0.00045" pos="0.01175 0 0" type="box"/>
                        <body name="finger_1_segment_link_4" pos="0.0235 0 0">
                            <inertial pos="0 0 0" quat="0 0.707107 0 0.707107" mass="0.00652778" diaginertia="1.62814e-06 1.2021e-06 4.26922e-07"/>
                            <joint name="finger_1_segment_joint_3" pos="0 0 0" axis="0 1 0" limited="true" range="-1 1" damping="0.01" stiffness="5"/>
                            <geom size="0.01175 0.014 0.00045" pos="0.01175 0 0" type="box" contype="0" conaffinity="0" group="1"/>
                            <geom size="0.01175 0.014 0.00045" pos="0.01175 0 0" type="box"/>
                            <body name="finger_1_segment_link_5" pos="0.0235 0 0">
                                <inertial pos="0 0 0" quat="0 0.707107 0 0.707107" mass="0.00652778" diaginertia="1.62814e-06 1.2021e-06 4.26922e-07"/>
                                <joint name="finger_1_segment_joint_4" pos="0 0 0" axis="0 1 0" limited="true" range="-1 1" damping="0.01" stiffness="5"/>
                                <geom size="0.01175 0.014 0.00045" pos="0.01175 0 0" type="box" contype="0" conaffinity="0" group="1"/>
                                <geom size="0.01175 0.014 0.00045" pos="0.01175 0 0" type="box"/>
                                <body name="finger_1_segment_link_6" pos="0.0235 0 0">
                                    <inertial pos="0 0 0" quat="0 0.707107 0 0.707107" mass="0.00652778" diaginertia="1.62814e-06 1.2021e-06 4.26922e-07"/>
                                    <joint name="finger_1_segment_joint_5" pos="0 0 0" axis="0 1 0" limited="true" range="-1 1" damping="0.01" stiffness="5"/>
                                    <geom size="0.01175 0.014 0.00045" pos="0.01175 0 0" type="box" contype="0" conaffinity="0" group="1"/>
                                    <geom size="0.01175 0.014 0.00045" pos="0.01175 0 0" type="box"/>
                                    <body name="finger_1_segment_link_7" pos="0.0235 0 0">
                                        <inertial pos="0 0 0" quat="0 0.707107 0 0.707107" mass="0.00652778" diaginertia="1.62814e-06 1.2021e-06 4.26922e-07"/>
                                        <joint name="finger_1_segment_joint_6" pos="0 0 0" axis="0 1 0" limited="true" range="-1 1" damping="0.01" stiffness="5"/>
                                        <geom size="0.01175 0.014 0.00045" pos="0.01175 0 0" type="box" contype="0" conaffinity="0" group="1"/>
                                        <geom size="0.01175 0.014 0.00045" pos="0.01175 0 0" type="box"/>
                                        <body name="finger_1_segment_link_8" pos="0.0235 0 0">
                                            <inertial pos="0 0 0" quat="0 0.707107 0 0.707107" mass="0.00652778" diaginertia="1.62814e-06 1.2021e-06 4.26922e-07"/>
                                            <joint name="finger_1_segment_joint_7" pos="0 0 0" axis="0 1 0" limited="true" range="-1 1" damping="0.01" stiffness="5"/>
                                            <geom size="0.01175 0.014 0.00045" pos="0.01175 0 0" type="box" contype="0" conaffinity="0" group="1"/>
                                            <geom size="0.01175 0.014 0.00045" pos="0.01175 0 0" type="box"/>
                                            <body name="finger_1_segment_link_9" pos="0.0235 0 0">
                                                <inertial pos="0 0 0" quat="0 0.707107 0 0.707107" mass="0.00652778" diaginertia="1.62814e-06 1.2021e-06 4.26922e-07"/>
                                                <joint name="finger_1_segment_joint_8" pos="0 0 0" axis="0 1 0" limited="true" range="-1 1" damping="0.01" stiffness="5"/>
                                                <geom size="0.01175 0.014 0.00045" pos="0.01175 0 0" type="box" contype="0" conaffinity="0" group="1"/>
                                                <geom size="0.01175 0.014 0.00045" pos="0.01175 0 0" type="box"/>
                                                <body name="finger_1_segment_link_10" pos="0.0235 0 0">
                                                    <inertial pos="0.01175 0 0" quat="0.5 0.5 0.5 0.5" mass="0.0130556" diaginertia="4.20667e-06 3.85754e-06 2.05506e-06"/>
                                                    <joint name="finger_1_segment_joint_9" pos="0 0 0" axis="0 1 0" limited="true" range="-1 1" damping="0.01" stiffness="5"/>
                                                    <geom size="0.01175 0.014 0.00045" pos="0.01175 0 0" type="box" contype="0" conaffinity="0" group="1"/>
                                                    <geom size="0.01175 0.014 0.00045" pos="0.01175 0 0" type="box"/>
                                                    <geom size="0.0175 0.014 0.00045" pos="0.0235 0 0.0175" quat="0.707107 0 -0.707107 0" type="box" contype="0" conaffinity="0" group="1"/>
                                                    <geom size="0.0175 0.014 0.00045" pos="0.0235 0 0.0175" quat="0.707107 0 -0.707107 0" type="box"/>
                                                </body>
                                            </body>
                                        </body>
                                    </body>
                                </body>
                            </body>
                        </body>
                    </body>
                </body>
            </body>
        </body>
        <body name="finger_2_intermediate" pos="0 0 1" quat="0.612372 0.353553 0.612372 -0.353553">
            <inertial pos="0 0 0" quat="0.37634 0.403447 0.585982 0.593484" mass="0.1" diaginertia="0.000166494 0.00015418 3.54554e-05"/>
            <joint name="finger_2_prismatic_joint" pos="0 0 0" axis="0 1 0" type="slide" limited="true" range="0.049 0.134" damping="1"/>
            <geom type="mesh" contype="0" conaffinity="0" group="1" mesh="nut visual"/>
            <geom type="mesh" mesh="nut collision"/>
            <body name="finger_2" pos="0 0 0">
                <inertial pos="0.00790482 -0.000428944 0" quat="0.291337 0.573406 0.417602 0.641823" mass="0.106528" diaginertia="0.000258979 0.000257241 4.77119e-05"/>
                <joint name="finger_2_revolute_joint" pos="0 0 0" axis="0 0 1" limited="true" range="-0.7 0.7" damping="1"/>
                <geom type="mesh" contype="0" conaffinity="0" group="1" mesh="platform only visual"/>
                <geom type="mesh" mesh="platform only collision"/>
                <geom size="0.01175 0.014 0.00045" pos="0.14075 -0.007 0" quat="0.707107 0.707107 0 0" type="box" contype="0" conaffinity="0" group="1"/>
                <geom size="0.01175 0.014 0.00045" pos="0.14075 -0.007 0" quat="0.707107 0.707107 0 0" type="box"/>
                <body name="finger_2_segment_link_2" pos="0.1525 -0.007 0" quat="0.707107 0.707107 0 0">
                    <inertial pos="0 0 0" quat="0 0.707107 0 0.707107" mass="0.00652778" diaginertia="1.62814e-06 1.2021e-06 4.26922e-07"/>
                    <joint name="finger_2_segment_joint_1" pos="0 0 0" axis="0 1 0" limited="true" range="-1 1" damping="0.01" stiffness="5"/>
                    <geom size="0.01175 0.014 0.00045" pos="0.01175 0 0" type="box" contype="0" conaffinity="0" group="1"/>
                    <geom size="0.01175 0.014 0.00045" pos="0.01175 0 0" type="box"/>
                    <body name="finger_2_segment_link_3" pos="0.0235 0 0">
                        <inertial pos="0 0 0" quat="0 0.707107 0 0.707107" mass="0.00652778" diaginertia="1.62814e-06 1.2021e-06 4.26922e-07"/>
                        <joint name="finger_2_segment_joint_2" pos="0 0 0" axis="0 1 0" limited="true" range="-1 1" damping="0.01" stiffness="5"/>
                        <geom size="0.01175 0.014 0.00045" pos="0.01175 0 0" type="box" contype="0" conaffinity="0" group="1"/>
                        <geom size="0.01175 0.014 0.00045" pos="0.01175 0 0" type="box"/>
                        <body name="finger_2_segment_link_4" pos="0.0235 0 0">
                            <inertial pos="0 0 0" quat="0 0.707107 0 0.707107" mass="0.00652778" diaginertia="1.62814e-06 1.2021e-06 4.26922e-07"/>
                            <joint name="finger_2_segment_joint_3" pos="0 0 0" axis="0 1 0" limited="true" range="-1 1" damping="0.01" stiffness="5"/>
                            <geom size="0.01175 0.014 0.00045" pos="0.01175 0 0" type="box" contype="0" conaffinity="0" group="1"/>
                            <geom size="0.01175 0.014 0.00045" pos="0.01175 0 0" type="box"/>
                            <body name="finger_2_segment_link_5" pos="0.0235 0 0">
                                <inertial pos="0 0 0" quat="0 0.707107 0 0.707107" mass="0.00652778" diaginertia="1.62814e-06 1.2021e-06 4.26922e-07"/>
                                <joint name="finger_2_segment_joint_4" pos="0 0 0" axis="0 1 0" limited="true" range="-1 1" damping="0.01" stiffness="5"/>
                                <geom size="0.01175 0.014 0.00045" pos="0.01175 0 0" type="box" contype="0" conaffinity="0" group="1"/>
                                <geom size="0.01175 0.014 0.00045" pos="0.01175 0 0" type="box"/>
                                <body name="finger_2_segment_link_6" pos="0.0235 0 0">
                                    <inertial pos="0 0 0" quat="0 0.707107 0 0.707107" mass="0.00652778" diaginertia="1.62814e-06 1.2021e-06 4.26922e-07"/>
                                    <joint name="finger_2_segment_joint_5" pos="0 0 0" axis="0 1 0" limited="true" range="-1 1" damping="0.01" stiffness="5"/>
                                    <geom size="0.01175 0.014 0.00045" pos="0.01175 0 0" type="box" contype="0" conaffinity="0" group="1"/>
                                    <geom size="0.01175 0.014 0.00045" pos="0.01175 0 0" type="box"/>
                                    <body name="finger_2_segment_link_7" pos="0.0235 0 0">
                                        <inertial pos="0 0 0" quat="0 0.707107 0 0.707107" mass="0.00652778" diaginertia="1.62814e-06 1.2021e-06 4.26922e-07"/>
                                        <joint name="finger_2_segment_joint_6" pos="0 0 0" axis="0 1 0" limited="true" range="-1 1" damping="0.01" stiffness="5"/>
                                        <geom size="0.01175 0.014 0.00045" pos="0.01175 0 0" type="box" contype="0" conaffinity="0" group="1"/>
                                        <geom size="0.01175 0.014 0.00045" pos="0.01175 0 0" type="box"/>
                                        <body name="finger_2_segment_link_8" pos="0.0235 0 0">
                                            <inertial pos="0 0 0" quat="0 0.707107 0 0.707107" mass="0.00652778" diaginertia="1.62814e-06 1.2021e-06 4.26922e-07"/>
                                            <joint name="finger_2_segment_joint_7" pos="0 0 0" axis="0 1 0" limited="true" range="-1 1" damping="0.01" stiffness="5"/>
                                            <geom size="0.01175 0.014 0.00045" pos="0.01175 0 0" type="box" contype="0" conaffinity="0" group="1"/>
                                            <geom size="0.01175 0.014 0.00045" pos="0.01175 0 0" type="box"/>
                                            <body name="finger_2_segment_link_9" pos="0.0235 0 0">
                                                <inertial pos="0 0 0" quat="0 0.707107 0 0.707107" mass="0.00652778" diaginertia="1.62814e-06 1.2021e-06 4.26922e-07"/>
                                                <joint name="finger_2_segment_joint_8" pos="0 0 0" axis="0 1 0" limited="true" range="-1 1" damping="0.01" stiffness="5"/>
                                                <geom size="0.01175 0.014 0.00045" pos="0.01175 0 0" type="box" contype="0" conaffinity="0" group="1"/>
                                                <geom size="0.01175 0.014 0.00045" pos="0.01175 0 0" type="box"/>
                                                <body name="finger_2_segment_link_10" pos="0.0235 0 0">
                                                    <inertial pos="0.01175 0 0" quat="0.5 0.5 0.5 0.5" mass="0.0130556" diaginertia="4.20667e-06 3.85754e-06 2.05506e-06"/>
                                                    <joint name="finger_2_segment_joint_9" pos="0 0 0" axis="0 1 0" limited="true" range="-1 1" damping="0.01" stiffness="5"/>
                                                    <geom size="0.01175 0.014 0.00045" pos="0.01175 0 0" type="box" contype="0" conaffinity="0" group="1"/>
                                                    <geom size="0.01175 0.014 0.00045" pos="0.01175 0 0" type="box"/>
                                                    <geom size="0.0175 0.014 0.00045" pos="0.0235 0 0.0175" quat="0.707107 0 -0.707107 0" type="box" contype="0" conaffinity="0" group="1"/>
                                                    <geom size="0.0175 0.014 0.00045" pos="0.0235 0 0.0175" quat="0.707107 0 -0.707107 0" type="box"/>
                                                </body>
                                            </body>
                                        </body>
                                    </body>
                                </body>
                            </body>
                        </body>
                    </body>
                </body>
            </body>
        </body>
        <body name="finger_3_intermediate" pos="0 0 1" quat="0.612372 -0.353553 0.612372 0.353553">
            <inertial pos="0 0 0" quat="0.37634 0.403447 0.585982 0.593484" mass="0.1" diaginertia="0.000166494 0.00015418 3.54554e-05"/>
            <joint name="finger_3_prismatic_joint" pos="0 0 0" axis="0 1 0" type="slide" limited="true" range="0.049 0.134" damping="1"/>
            <geom type="mesh" contype="0" conaffinity="0" group="1" mesh="nut visual"/>
            <geom type="mesh" mesh="nut collision"/>
            <body name="finger_3" pos="0 0 0">
                <inertial pos="0.00790482 -0.000428944 0" quat="0.291337 0.573406 0.417602 0.641823" mass="0.106528" diaginertia="0.000258979 0.000257241 4.77119e-05"/>
                <joint name="finger_3_revolute_joint" pos="0 0 0" axis="0 0 1" limited="true" range="-0.7 0.7" damping="1"/>
                <geom type="mesh" contype="0" conaffinity="0" group="1" mesh="platform only visual"/>
                <geom type="mesh" mesh="platform only collision"/>
                <geom size="0.01175 0.014 0.00045" pos="0.14075 -0.007 0" quat="0.707107 0.707107 0 0" type="box" contype="0" conaffinity="0" group="1"/>
                <geom size="0.01175 0.014 0.00045" pos="0.14075 -0.007 0" quat="0.707107 0.707107 0 0" type="box"/>
                <body name="finger_3_segment_link_2" pos="0.1525 -0.007 0" quat="0.707107 0.707107 0 0">
                    <inertial pos="0 0 0" quat="0 0.707107 0 0.707107" mass="0.00652778" diaginertia="1.62814e-06 1.2021e-06 4.26922e-07"/>
                    <joint name="finger_3_segment_joint_1" pos="0 0 0" axis="0 1 0" limited="true" range="-1 1" damping="0.01" stiffness="5"/>
                    <geom size="0.01175 0.014 0.00045" pos="0.01175 0 0" type="box" contype="0" conaffinity="0" group="1"/>
                    <geom size="0.01175 0.014 0.00045" pos="0.01175 0 0" type="box"/>
                    <body name="finger_3_segment_link_3" pos="0.0235 0 0">
                        <inertial pos="0 0 0" quat="0 0.707107 0 0.707107" mass="0.00652778" diaginertia="1.62814e-06 1.2021e-06 4.26922e-07"/>
                        <joint name="finger_3_segment_joint_2" pos="0 0 0" axis="0 1 0" limited="true" range="-1 1" damping="0.01" stiffness="5"/>
                        <geom size="0.01175 0.014 0.00045" pos="0.01175 0 0" type="box" contype="0" conaffinity="0" group="1"/>
                        <geom size="0.01175 0.014 0.00045" pos="0.01175 0 0" type="box"/>
                        <body name="finger_3_segment_link_4" pos="0.0235 0 0">
                            <inertial pos="0 0 0" quat="0 0.707107 0 0.707107" mass="0.00652778" diaginertia="1.62814e-06 1.2021e-06 4.26922e-07"/>
                            <joint name="finger_3_segment_joint_3" pos="0 0 0" axis="0 1 0" limited="true" range="-1 1" damping="0.01" stiffness="5"/>
                            <geom size="0.01175 0.014 0.00045" pos="0.01175 0 0" type="box" contype="0" conaffinity="0" group="1"/>
                            <geom size="0.01175 0.014 0.00045" pos="0.01175 0 0" type="box"/>
                            <body name="finger_3_segment_link_5" pos="0.0235 0 0">
                                <inertial pos="0 0 0" quat="0 0.707107 0 0.707107" mass="0.00652778" diaginertia="1.62814e-06 1.2021e-06 4.26922e-07"/>
                                <joint name="finger_3_segment_joint_4" pos="0 0 0" axis="0 1 0" limited="true" range="-1 1" damping="0.01" stiffness="5"/>
                                <geom size="0.01175 0.014 0.00045" pos="0.01175 0 0" type="box" contype="0" conaffinity="0" group="1"/>
                                <geom size="0.01175 0.014 0.00045" pos="0.01175 0 0" type="box"/>
                                <body name="finger_3_segment_link_6" pos="0.0235 0 0">
                                    <inertial pos="0 0 0" quat="0 0.707107 0 0.707107" mass="0.00652778" diaginertia="1.62814e-06 1.2021e-06 4.26922e-07"/>
                                    <joint name="finger_3_segment_joint_5" pos="0 0 0" axis="0 1 0" limited="true" range="-1 1" damping="0.01" stiffness="5"/>
                                    <geom size="0.01175 0.014 0.00045" pos="0.01175 0 0" type="box" contype="0" conaffinity="0" group="1"/>
                                    <geom size="0.01175 0.014 0.00045" pos="0.01175 0 0" type="box"/>
                                    <body name="finger_3_segment_link_7" pos="0.0235 0 0">
                                        <inertial pos="0 0 0" quat="0 0.707107 0 0.707107" mass="0.00652778" diaginertia="1.62814e-06 1.2021e-06 4.26922e-07"/>
                                        <joint name="finger_3_segment_joint_6" pos="0 0 0" axis="0 1 0" limited="true" range="-1 1" damping="0.01" stiffness="5"/>
                                        <geom size="0.01175 0.014 0.00045" pos="0.01175 0 0" type="box" contype="0" conaffinity="0" group="1"/>
                                        <geom size="0.01175 0.014 0.00045" pos="0.01175 0 0" type="box"/>
                                        <body name="finger_3_segment_link_8" pos="0.0235 0 0">
                                            <inertial pos="0 0 0" quat="0 0.707107 0 0.707107" mass="0.00652778" diaginertia="1.62814e-06 1.2021e-06 4.26922e-07"/>
                                            <joint name="finger_3_segment_joint_7" pos="0 0 0" axis="0 1 0" limited="true" range="-1 1" damping="0.01" stiffness="5"/>
                                            <geom size="0.01175 0.014 0.00045" pos="0.01175 0 0" type="box" contype="0" conaffinity="0" group="1"/>
                                            <geom size="0.01175 0.014 0.00045" pos="0.01175 0 0" type="box"/>
                                            <body name="finger_3_segment_link_9" pos="0.0235 0 0">
                                                <inertial pos="0 0 0" quat="0 0.707107 0 0.707107" mass="0.00652778" diaginertia="1.62814e-06 1.2021e-06 4.26922e-07"/>
                                                <joint name="finger_3_segment_joint_8" pos="0 0 0" axis="0 1 0" limited="true" range="-1 1" damping="0.01" stiffness="5"/>
                                                <geom size="0.01175 0.014 0.00045" pos="0.01175 0 0" type="box" contype="0" conaffinity="0" group="1"/>
                                                <geom size="0.01175 0.014 0.00045" pos="0.01175 0 0" type="box"/>
                                                <body name="finger_3_segment_link_10" pos="0.0235 0 0">
                                                    <inertial pos="0.01175 0 0" quat="0.5 0.5 0.5 0.5" mass="0.0130556" diaginertia="4.20667e-06 3.85754e-06 2.05506e-06"/>
                                                    <joint name="finger_3_segment_joint_9" pos="0 0 0" axis="0 1 0" limited="true" range="-1 1" damping="0.01" stiffness="5"/>
                                                    <geom size="0.01175 0.014 0.00045" pos="0.01175 0 0" type="box" contype="0" conaffinity="0" group="1"/>
                                                    <geom size="0.01175 0.014 0.00045" pos="0.01175 0 0" type="box"/>
                                                    <geom size="0.0175 0.014 0.00045" pos="0.0235 0 0.0175" quat="0.707107 0 -0.707107 0" type="box" contype="0" conaffinity="0" group="1"/>
                                                    <geom size="0.0175 0.014 0.00045" pos="0.0235 0 0.0175" quat="0.707107 0 -0.707107 0" type="box"/>
                                                </body>
                                            </body>
                                        </body>
                                    </body>
                                </body>
                            </body>
                        </body>
                    </body>
                </body>
            </body>
        </body>
        <body name="palm" pos="0 0 1" quat="0 0.707107 0 -0.707107">
            <inertial pos="0 0 0" mass="0.05" diaginertia="1e-05 1e-05 1e-05"/>
            <joint name="palm_prismatic_joint" pos="0 0 0" axis="1 0 0" type="slide" limited="true" range="0 0.165" damping="1"/>
            <geom type="mesh" contype="0" conaffinity="0" group="1" mesh="palm visual"/>
            <geom type="mesh" mesh="palm collision"/>
        </body>
    </worldbody>
<keyframe>
    <key name="initial pose" time="0" qpos="0.132 0.0 0 0 0 0 0 0 0 0 0  0.132 0.0 0 0 0 0 0 0 0 0 0  0.132 0.0 0 0 0 0 0 0 0 0 0  0.0"/>
  </keyframe><actuator>
    
  <motor name="finger_1_prismatic_joint_actuator" joint="finger_1_prismatic_joint"/>

  <motor name="finger_1_revolute_joint_actuator" joint="finger_1_revolute_joint"/>

  <motor name="finger_2_prismatic_joint_actuator" joint="finger_2_prismatic_joint"/>

  <motor name="finger_2_revolute_joint_actuator" joint="finger_2_revolute_joint"/>

  <motor name="finger_3_prismatic_joint_actuator" joint="finger_3_prismatic_joint"/>

  <motor name="finger_3_revolute_joint_actuator" joint="finger_3_revolute_joint"/>

  <motor name="palm_prismatic_joint_actuator" joint="palm_prismatic_joint"/>

    
  <motor name="finger_1_segment_joint_1_actuator" joint="finger_1_segment_joint_1"/>

  <motor name="finger_1_segment_joint_2_actuator" joint="finger_1_segment_joint_2"/>

  <motor name="finger_1_segment_joint_3_actuator" joint="finger_1_segment_joint_3"/>

  <motor name="finger_1_segment_joint_4_actuator" joint="finger_1_segment_joint_4"/>

  <motor name="finger_1_segment_joint_5_actuator" joint="finger_1_segment_joint_5"/>

  <motor name="finger_1_segment_joint_6_actuator" joint="finger_1_segment_joint_6"/>

  <motor name="finger_1_segment_joint_7_actuator" joint="finger_1_segment_joint_7"/>

  <motor name="finger_1_segment_joint_8_actuator" joint="finger_1_segment_joint_8"/>

  <motor name="finger_1_segment_joint_9_actuator" joint="finger_1_segment_joint_9"/>

  <motor name="finger_2_segment_joint_1_actuator" joint="finger_2_segment_joint_1"/>

  <motor name="finger_2_segment_joint_2_actuator" joint="finger_2_segment_joint_2"/>

  <motor name="finger_2_segment_joint_3_actuator" joint="finger_2_segment_joint_3"/>

  <motor name="finger_2_segment_joint_4_actuator" joint="finger_2_segment_joint_4"/>

  <motor name="finger_2_segment_joint_5_actuator" joint="finger_2_segment_joint_5"/>

  <motor name="finger_2_segment_joint_6_actuator" joint="finger_2_segment_joint_6"/>

  <motor name="finger_2_segment_joint_7_actuator" joint="finger_2_segment_joint_7"/>

  <motor name="finger_2_segment_joint_8_actuator" joint="finger_2_segment_joint_8"/>

  <motor name="finger_2_segment_joint_9_actuator" joint="finger_2_segment_joint_9"/>

  <motor name="finger_3_segment_joint_1_actuator" joint="finger_3_segment_joint_1"/>

  <motor name="finger_3_segment_joint_2_actuator" joint="finger_3_segment_joint_2"/>

  <motor name="finger_3_segment_joint_3_actuator" joint="finger_3_segment_joint_3"/>

  <motor name="finger_3_segment_joint_4_actuator" joint="finger_3_segment_joint_4"/>

  <motor name="finger_3_segment_joint_5_actuator" joint="finger_3_segment_joint_5"/>

  <motor name="finger_3_segment_joint_6_actuator" joint="finger_3_segment_joint_6"/>

  <motor name="finger_3_segment_joint_7_actuator" joint="finger_3_segment_joint_7"/>

  <motor name="finger_3_segment_joint_8_actuator" joint="finger_3_segment_joint_8"/>

  <motor name="finger_3_segment_joint_9_actuator" joint="finger_3_segment_joint_9"/>

  </actuator></mujoco>